Workbook

Sheet Resumen
A1: Pokémon TCG: 30th Celebration (30.º aniversario) – Lista de cartas (versión en inglés)
A2: Lanzamiento mundial: 16 de septiembre de 2026. Todas las cartas son foil.
A4: Sección | B4: Cartas | C4: Tengo | D4: Faltan | E4: % completado
A5: Set principal (incl. 30 Pikachu) | B5: =COUNTA('Set principal'!A2:A500) | C5: =COUNTIF('Set principal'!F2:F500,"Sí") | D5: =B5-C5 | E5: =IF(B5=0,0,C5/B5)
A6: Secretas (129–158 + 3 Mew RGB) | B6: =COUNTA(Secretas!A2:A500) | C6: =COUNTIF(Secretas!G2:G500,"Sí") | D6: =B6-C6 | E6: =IF(B6=0,0,C6/B6)
A7: Classic Collection | B7: =COUNTA('Classic Collection'!A2:A500) | C7: =COUNTIF('Classic Collection'!D2:D500,"Sí") | D7: =B7-C7 | E7: =IF(B7=0,0,C7/B7)
A8: Energías básicas | B8: =COUNTA(Energías!A2:A500) | C8: =COUNTIF(Energías!B2:B500,"Sí") | D8: =B8-C8 | E8: =IF(B8=0,0,C8/B8)
A9: TOTAL | B9: =SUM(B5:B8) | C9: =SUM(C5:C8) | D9: =SUM(D5:D8) | E9: =IF(B9=0,0,C9/B9)
A11: Desglose por rareza (set principal + secretas)
A12: Rareza | B12: Cartas
A13: Common | B13: =COUNTIF('Set principal'!D2:D500,A13)
A14: Rare | B14: =COUNTIF('Set principal'!D2:D500,A14)
A15: Double Rare | B15: =COUNTIF('Set principal'!D2:D500,A15)
A16: Pikachu Rare | B16: =COUNTIF('Set principal'!D2:D500,A16)
A17: Illustration Rare | B17: =COUNTIF(Secretas!D2:D500,A17)
A18: Special Illustration Rare | B18: =COUNTIF(Secretas!D2:D500,A18)
A19: Futuristic Rare | B19: =COUNTIF(Secretas!D2:D500,A19)
A20: Secret Rare (RGB) | B20: =COUNTIF(Secretas!D2:D500,A20)
A22: Notas y fuentes
A23: • Cómo usarlo: marca «Sí» en la columna «¿La tengo?» de cada hoja; este resumen se actualiza solo.
A24: • Total de cartas de la expansión en inglés: 199 (128 set principal + 30 secretas numeradas + 3 Mew RGB + 30 Classic Collection + 8 Energías).
A25: • Fuentes: lista oficial de The Pokémon Company (galería), VICE (16/09/2026), PokéBeach y TCGscreener (ilustradores y rarezas).
A26: • Los Mew RGB (R/G/B) no aparecen en la lista oficial; su existencia está confirmada por hallazgos en sobres y datos de Pokémon TCG Live.
A27: • 4 secretas (143, 151, 152, 154) no tenían imagen en inglés en las fuentes consultadas: su ilustrador queda en blanco. Umbreon ex 092 también.
A28: • Imágenes: columna «Imagen» (Excel 365 / Google Sheets, requiere internet), cargadas desde Limitless TCG. Las Energías no tienen imagen.
A29: • Las promos de productos (Nidorina, Ditto, Eevee, etc.) NO forman parte de las 199 cartas y no se incluyen.
A30: • El Classic Collection no es legal en torneos; el resto del set sí desde el 25/09/2026.

Sheet Set principal
A1: N.º | B1: Nombre | C1: Tipo | D1: Rareza | E1: Ilustrador | F1: ¿La tengo? | G1: Imagen
A2: 001/128 | B2: Exeggcute | C2: Planta | D2: Common | E2: Nelnal | F2: Sí | G2: =IFERROR(_xlfn.IMAGE("https://limitlesstcg.nyc3.cdn.digitaloceanspaces.com/tpci/30C/30C_001_R_EN_SM.png","001/128"),"Sin imagen")
A3: 002/128 | B3: Alolan Exeggutor | C3: Planta | D3: Common | E3: Oswaldo KATO | F3: Sí | G3: =IFERROR(_xlfn.IMAGE("https://limitlesstcg.nyc3.cdn.digitaloceanspaces.com/tpci/30C/30C_002_R_EN_SM.png","002/128"),"Sin imagen")
A4: 003/128 | B4: Volbeat | C4: Planta | D4: Common | E4: Yoriyuki Ikegami | F4: Sí | G4: =IFERROR(_xlfn.IMAGE("https://limitlesstcg.nyc3.cdn.digitaloceanspaces.com/tpci/30C/30C_003_R_EN_SM.png","003/128"),"Sin imagen")
A5: 004/128 | B5: Illumise | C5: Planta | D5: Common | E5: Shibuzoh. | G5: =IFERROR(_xlfn.IMAGE("https://limitlesstcg.nyc3.cdn.digitaloceanspaces.com/tpci/30C/30C_004_R_EN_SM.png","004/128"),"Sin imagen")
A6: 005/128 | B6: Tropius | C6: Planta | D6: Common | E6: Minahamu | G6: =IFERROR(_xlfn.IMAGE("https://limitlesstcg.nyc3.cdn.digitaloceanspaces.com/tpci/30C/30C_005_R_EN_SM.png","005/128"),"Sin imagen")
A7: 006/128 | B7: Cherubi | C7: Planta | D7: Common | E7: Kurata So | F7: Sí | G7: =IFERROR(_xlfn.IMAGE("https://limitlesstcg.nyc3.cdn.digitaloceanspaces.com/tpci/30C/30C_006_R_EN_SM.png","006/128"),"Sin imagen")
A8: 007/128 | B8: Cherrim | C8: Planta | D8: Common | E8: takashi shiraishi | G8: =IFERROR(_xlfn.IMAGE("https://limitlesstcg.nyc3.cdn.digitaloceanspaces.com/tpci/30C/30C_007_R_EN_SM.png","007/128"),"Sin imagen")
A9: 008/128 | B9: Vivillon | C9: Planta | D9: Common | E9: Jerky | G9: =IFERROR(_xlfn.IMAGE("https://limitlesstcg.nyc3.cdn.digitaloceanspaces.com/tpci/30C/30C_008_R_EN_SM.png","008/128"),"Sin imagen")
A10: 009/128 | B10: Vulpix | C10: Fuego | D10: Common | E10: miki kudo | G10: =IFERROR(_xlfn.IMAGE("https://limitlesstcg.nyc3.cdn.digitaloceanspaces.com/tpci/30C/30C_009_R_EN_SM.png","009/128"),"Sin imagen")
A11: 010/128 | B11: Ninetales | C11: Fuego | D11: Common | E11: kodama | G11: =IFERROR(_xlfn.IMAGE("https://limitlesstcg.nyc3.cdn.digitaloceanspaces.com/tpci/30C/30C_010_R_EN_SM.png","010/128"),"Sin imagen")
A12: 011/128 | B12: Moltres | C12: Fuego | D12: Common | E12: HYOGONOSUKE | G12: =IFERROR(_xlfn.IMAGE("https://limitlesstcg.nyc3.cdn.digitaloceanspaces.com/tpci/30C/30C_011_R_EN_SM.png","011/128"),"Sin imagen")
A13: 012/128 | B13: Ho-Oh | C13: Fuego | D13: Rare | E13: Anesaki Dynamic | G13: =IFERROR(_xlfn.IMAGE("https://limitlesstcg.nyc3.cdn.digitaloceanspaces.com/tpci/30C/30C_012_R_EN_SM.png","012/128"),"Sin imagen")
A14: 013/128 | B14: Victini | C14: Fuego | D14: Common | E14: Jiro Sasumo | G14: =IFERROR(_xlfn.IMAGE("https://limitlesstcg.nyc3.cdn.digitaloceanspaces.com/tpci/30C/30C_013_R_EN_SM.png","013/128"),"Sin imagen")
A15: 014/128 | B15: Reshiram | C15: Fuego | D15: Rare | E15: Uta | G15: =IFERROR(_xlfn.IMAGE("https://limitlesstcg.nyc3.cdn.digitaloceanspaces.com/tpci/30C/30C_014_R_EN_SM.png","014/128"),"Sin imagen")
A16: 015/128 | B16: Fuecoco ex | C16: Fuego | D16: Double Rare | E16: 5ban Graphics | G16: =IFERROR(_xlfn.IMAGE("https://limitlesstcg.nyc3.cdn.digitaloceanspaces.com/tpci/30C/30C_015_R_EN_SM.png","015/128"),"Sin imagen")
A17: 016/128 | B17: Slowpoke | C17: Agua | D17: Common | E17: Uninori | G17: =IFERROR(_xlfn.IMAGE("https://limitlesstcg.nyc3.cdn.digitaloceanspaces.com/tpci/30C/30C_016_R_EN_SM.png","016/128"),"Sin imagen")
A18: 017/128 | B18: Lapras | C18: Agua | D18: Common | E18: Masa | G18: =IFERROR(_xlfn.IMAGE("https://limitlesstcg.nyc3.cdn.digitaloceanspaces.com/tpci/30C/30C_017_R_EN_SM.png","017/128"),"Sin imagen")
A19: 018/128 | B19: Articuno | C19: Agua | D19: Common | E19: HYOGONOSUKE | G19: =IFERROR(_xlfn.IMAGE("https://limitlesstcg.nyc3.cdn.digitaloceanspaces.com/tpci/30C/30C_018_R_EN_SM.png","018/128"),"Sin imagen")
A20: 019/128 | B20: Kyogre | C20: Agua | D20: Rare | E20: Tonji Matsuno | G20: =IFERROR(_xlfn.IMAGE("https://limitlesstcg.nyc3.cdn.digitaloceanspaces.com/tpci/30C/30C_019_R_EN_SM.png","019/128"),"Sin imagen")
A21: 020/128 | B21: Palkia | C21: Agua | D21: Rare | E21: kawayoo | G21: =IFERROR(_xlfn.IMAGE("https://limitlesstcg.nyc3.cdn.digitaloceanspaces.com/tpci/30C/30C_020_R_EN_SM.png","020/128"),"Sin imagen")
A22: 021/128 | B22: Greninja ex | C22: Agua | D22: Double Rare | E22: 5ban Graphics | G22: =IFERROR(_xlfn.IMAGE("https://limitlesstcg.nyc3.cdn.digitaloceanspaces.com/tpci/30C/30C_021_R_EN_SM.png","021/128"),"Sin imagen")
A23: 022/128 | B23: Wishiwashi | C23: Agua | D23: Common | E23: Narano | G23: =IFERROR(_xlfn.IMAGE("https://limitlesstcg.nyc3.cdn.digitaloceanspaces.com/tpci/30C/30C_022_R_EN_SM.png","022/128"),"Sin imagen")
A24: 023/128 | B24: Pikachu (01/30) | C24: Rayo | D24: Pikachu Rare | E24: Ken Sugimori | G24: =IFERROR(_xlfn.IMAGE("https://limitlesstcg.nyc3.cdn.digitaloceanspaces.com/tpci/30C/30C_023_R_EN_SM.png","023/128"),"Sin imagen")
A25: 024/128 | B25: Pikachu (02/30) | C25: Rayo | D25: Pikachu Rare | E25: danciao | G25: =IFERROR(_xlfn.IMAGE("https://limitlesstcg.nyc3.cdn.digitaloceanspaces.com/tpci/30C/30C_024_R_EN_SM.png","024/128"),"Sin imagen")
A26: 025/128 | B26: Pikachu (03/30) | C26: Rayo | D26: Pikachu Rare | E26: satoma | G26: =IFERROR(_xlfn.IMAGE("https://limitlesstcg.nyc3.cdn.digitaloceanspaces.com/tpci/30C/30C_025_R_EN_SM.png","025/128"),"Sin imagen")
A27: 026/128 | B27: Pikachu (04/30) | C27: Rayo | D27: Pikachu Rare | E27: Takeshi Nakamura | G27: =IFERROR(_xlfn.IMAGE("https://limitlesstcg.nyc3.cdn.digitaloceanspaces.com/tpci/30C/30C_026_R_EN_SM.png","026/128"),"Sin imagen")
A28: 027/128 | B28: Pikachu (05/30) | C28: Rayo | D28: Pikachu Rare | E28: Asako Ito | G28: =IFERROR(_xlfn.IMAGE("https://limitlesstcg.nyc3.cdn.digitaloceanspaces.com/tpci/30C/30C_027_R_EN_SM.png","027/128"),"Sin imagen")
A29: 028/128 | B29: Pikachu (06/30) | C29: Rayo | D29: Pikachu Rare | E29: sowsow | G29: =IFERROR(_xlfn.IMAGE("https://limitlesstcg.nyc3.cdn.digitaloceanspaces.com/tpci/30C/30C_028_R_EN_SM.png","028/128"),"Sin imagen")
A30: 029/128 | B30: Pikachu (07/30) | C30: Rayo | D30: Pikachu Rare | E30: James Turner | G30: =IFERROR(_xlfn.IMAGE("https://limitlesstcg.nyc3.cdn.digitaloceanspaces.com/tpci/30C/30C_029_R_EN_SM.png","029/128"),"Sin imagen")
A31: 030/128 | B31: Pikachu (08/30) | C31: Rayo | D31: Pikachu Rare | E31: DOM | G31: =IFERROR(_xlfn.IMAGE("https://limitlesstcg.nyc3.cdn.digitaloceanspaces.com/tpci/30C/30C_030_R_EN_SM.png","030/128"),"Sin imagen")
A32: 031/128 | B32: Pikachu (09/30) | C32: Rayo | D32: Pikachu Rare | E32: Atsushi Furusawa | G32: =IFERROR(_xlfn.IMAGE("https://limitlesstcg.nyc3.cdn.digitaloceanspaces.com/tpci/30C/30C_031_R_EN_SM.png","031/128"),"Sin imagen")
A33: 032/128 | B33: Pikachu (10/30) | C33: Rayo | D33: Pikachu Rare | E33: Tomokazu Komiya | G33: =IFERROR(_xlfn.IMAGE("https://limitlesstcg.nyc3.cdn.digitaloceanspaces.com/tpci/30C/30C_032_R_EN_SM.png","032/128"),"Sin imagen")
A34: 033/128 | B34: Pikachu (11/30) | C34: Rayo | D34: Pikachu Rare | E34: Narumi Sato | G34: =IFERROR(_xlfn.IMAGE("https://limitlesstcg.nyc3.cdn.digitaloceanspaces.com/tpci/30C/30C_033_R_EN_SM.png","033/128"),"Sin imagen")
A35: 034/128 | B35: Pikachu (12/30) | C35: Rayo | D35: Pikachu Rare | E35: USGMEN | G35: =IFERROR(_xlfn.IMAGE("https://limitlesstcg.nyc3.cdn.digitaloceanspaces.com/tpci/30C/30C_034_R_EN_SM.png","034/128"),"Sin imagen")
A36: 035/128 | B36: Pikachu (13/30) | C36: Rayo | D36: Pikachu Rare | E36: Susumu Maeya | G36: =IFERROR(_xlfn.IMAGE("https://limitlesstcg.nyc3.cdn.digitaloceanspaces.com/tpci/30C/30C_035_R_EN_SM.png","035/128"),"Sin imagen")
A37: 036/128 | B37: Pikachu (14/30) | C37: Rayo | D37: Pikachu Rare | E37: OKACHEKE | G37: =IFERROR(_xlfn.IMAGE("https://limitlesstcg.nyc3.cdn.digitaloceanspaces.com/tpci/30C/30C_036_R_EN_SM.png","036/128"),"Sin imagen")
A38: 037/128 | B38: Pikachu (15/30) | C38: Rayo | D38: Pikachu Rare | E38: Yuu Nishida | G38: =IFERROR(_xlfn.IMAGE("https://limitlesstcg.nyc3.cdn.digitaloceanspaces.com/tpci/30C/30C_037_R_EN_SM.png","037/128"),"Sin imagen")
A39: 038/128 | B39: Pikachu (16/30) | C39: Rayo | D39: Pikachu Rare | E39: Tetsu Kayama | G39: =IFERROR(_xlfn.IMAGE("https://limitlesstcg.nyc3.cdn.digitaloceanspaces.com/tpci/30C/30C_038_R_EN_SM.png","038/128"),"Sin imagen")
A40: 039/128 | B40: Pikachu (17/30) | C40: Rayo | D40: Pikachu Rare | E40: Teeziro | G40: =IFERROR(_xlfn.IMAGE("https://limitlesstcg.nyc3.cdn.digitaloceanspaces.com/tpci/30C/30C_039_R_EN_SM.png","039/128"),"Sin imagen")
...

Sheet Secretas
A1: N.º | B1: Nombre | C1: Tipo | D1: Rareza | E1: Ilustrador | F1: Notas | G1: ¿La tengo? | H1: Imagen
A2: 129/128 | B2: Alolan Exeggutor | C2: Planta | D2: Illustration Rare | E2: AYUMI ODASHIMA | H2: =IFERROR(_xlfn.IMAGE("https://limitlesstcg.nyc3.cdn.digitaloceanspaces.com/tpci/30C/30C_129_R_EN_SM.png","129/128"),"Sin imagen")
A3: 130/128 | B3: Moltres | C3: Fuego | D3: Illustration Rare | E3: mashu | H3: =IFERROR(_xlfn.IMAGE("https://limitlesstcg.nyc3.cdn.digitaloceanspaces.com/tpci/30C/30C_130_R_EN_SM.png","130/128"),"Sin imagen")
A4: 131/128 | B4: Lapras | C4: Agua | D4: Illustration Rare | E4: Ameikart | H4: =IFERROR(_xlfn.IMAGE("https://limitlesstcg.nyc3.cdn.digitaloceanspaces.com/tpci/30C/30C_131_R_EN_SM.png","131/128"),"Sin imagen")
A5: 132/128 | B5: Articuno | C5: Agua | D5: Illustration Rare | E5: mashu | H5: =IFERROR(_xlfn.IMAGE("https://limitlesstcg.nyc3.cdn.digitaloceanspaces.com/tpci/30C/30C_132_R_EN_SM.png","132/128"),"Sin imagen")
A6: 133/128 | B6: Zapdos | C6: Rayo | D6: Illustration Rare | E6: mashu | H6: =IFERROR(_xlfn.IMAGE("https://limitlesstcg.nyc3.cdn.digitaloceanspaces.com/tpci/30C/30C_133_R_EN_SM.png","133/128"),"Sin imagen")
A7: 134/128 | B7: Toxtricity | C7: Rayo | D7: Illustration Rare | E7: Kazumasa Yasukuni | H7: =IFERROR(_xlfn.IMAGE("https://limitlesstcg.nyc3.cdn.digitaloceanspaces.com/tpci/30C/30C_134_R_EN_SM.png","134/128"),"Sin imagen")
A8: 135/128 | B8: Morpeko | C8: Rayo | D8: Illustration Rare | E8: Yoshimi Miyoshi | H8: =IFERROR(_xlfn.IMAGE("https://limitlesstcg.nyc3.cdn.digitaloceanspaces.com/tpci/30C/30C_135_R_EN_SM.png","135/128"),"Sin imagen")
A9: 136/128 | B9: Drifloon | C9: Psíquico | D9: Illustration Rare | E9: Whisker | H9: =IFERROR(_xlfn.IMAGE("https://limitlesstcg.nyc3.cdn.digitaloceanspaces.com/tpci/30C/30C_136_R_EN_SM.png","136/128"),"Sin imagen")
A10: 137/128 | B10: Chandelure | C10: Psíquico | D10: Illustration Rare | E10: YASHIRO Nanaco | H10: =IFERROR(_xlfn.IMAGE("https://limitlesstcg.nyc3.cdn.digitaloceanspaces.com/tpci/30C/30C_137_R_EN_SM.png","137/128"),"Sin imagen")
A11: 138/128 | B11: Lycanroc | C11: Lucha | D11: Illustration Rare | E11: Raita Kazama | H11: =IFERROR(_xlfn.IMAGE("https://limitlesstcg.nyc3.cdn.digitaloceanspaces.com/tpci/30C/30C_138_R_EN_SM.png","138/128"),"Sin imagen")
A12: 139/128 | B12: Alolan Meowth | C12: Oscuridad | D12: Illustration Rare | E12: OKUBO | H12: =IFERROR(_xlfn.IMAGE("https://limitlesstcg.nyc3.cdn.digitaloceanspaces.com/tpci/30C/30C_139_R_EN_SM.png","139/128"),"Sin imagen")
A13: 140/128 | B13: Scraggy | C13: Oscuridad | D13: Illustration Rare | E13: GOSSAN | H13: =IFERROR(_xlfn.IMAGE("https://limitlesstcg.nyc3.cdn.digitaloceanspaces.com/tpci/30C/30C_140_R_EN_SM.png","140/128"),"Sin imagen")
A14: 141/128 | B14: Galarian Meowth | C14: Metal | D14: Illustration Rare | E14: OKUBO | H14: =IFERROR(_xlfn.IMAGE("https://limitlesstcg.nyc3.cdn.digitaloceanspaces.com/tpci/30C/30C_141_R_EN_SM.png","141/128"),"Sin imagen")
A15: 142/128 | B15: Gholdengo | C15: Metal | D15: Illustration Rare | E15: toriyufu | H15: =IFERROR(_xlfn.IMAGE("https://limitlesstcg.nyc3.cdn.digitaloceanspaces.com/tpci/30C/30C_142_R_EN_SM.png","142/128"),"Sin imagen")
A16: 143/128 | B16: Kommo-o | C16: Dragón | D16: Illustration Rare | F16: Ilustrador aún no confirmado en las fuentes | H16: =IFERROR(_xlfn.IMAGE("https://limitlesstcg.nyc3.cdn.digitaloceanspaces.com/tpci/30C/30C_143_R_EN_SM.png","143/128"),"Sin imagen")
A17: 144/128 | B17: Meowth | C17: Incoloro | D17: Illustration Rare | E17: OKUBO | H17: =IFERROR(_xlfn.IMAGE("https://limitlesstcg.nyc3.cdn.digitaloceanspaces.com/tpci/30C/30C_144_R_EN_SM.png","144/128"),"Sin imagen")
A18: 145/128 | B18: Hisuian Zorua | C18: Incoloro | D18: Illustration Rare | E18: 0313 | H18: =IFERROR(_xlfn.IMAGE("https://limitlesstcg.nyc3.cdn.digitaloceanspaces.com/tpci/30C/30C_145_R_EN_SM.png","145/128"),"Sin imagen")
A19: 146/128 | B19: Maushold | C19: Incoloro | D19: Illustration Rare | E19: osare | H19: =IFERROR(_xlfn.IMAGE("https://limitlesstcg.nyc3.cdn.digitaloceanspaces.com/tpci/30C/30C_146_R_EN_SM.png","146/128"),"Sin imagen")
A20: 147/128 | B20: Fuecoco ex | C20: Fuego | D20: Special Illustration Rare | E20: Atsushi Furusawa | H20: =IFERROR(_xlfn.IMAGE("https://limitlesstcg.nyc3.cdn.digitaloceanspaces.com/tpci/30C/30C_147_R_EN_SM.png","147/128"),"Sin imagen")
A21: 148/128 | B21: Greninja ex | C21: Agua | D21: Special Illustration Rare | E21: GIDORA | H21: =IFERROR(_xlfn.IMAGE("https://limitlesstcg.nyc3.cdn.digitaloceanspaces.com/tpci/30C/30C_148_R_EN_SM.png","148/128"),"Sin imagen")
A22: 149/128 | B22: Pikachu ex (día) | C22: Rayo | D22: Special Illustration Rare | E22: kantaro | H22: =IFERROR(_xlfn.IMAGE("https://limitlesstcg.nyc3.cdn.digitaloceanspaces.com/tpci/30C/30C_149_R_EN_SM.png","149/128"),"Sin imagen")
A23: 150/128 | B23: Pikachu ex (noche) | C23: Rayo | D23: Special Illustration Rare | E23: kantaro | H23: =IFERROR(_xlfn.IMAGE("https://limitlesstcg.nyc3.cdn.digitaloceanspaces.com/tpci/30C/30C_150_R_EN_SM.png","150/128"),"Sin imagen")
A24: 151/128 | B24: Mewtwo ex | C24: Psíquico | D24: Special Illustration Rare | F24: Ilustrador aún no confirmado en las fuentes | H24: =IFERROR(_xlfn.IMAGE("https://limitlesstcg.nyc3.cdn.digitaloceanspaces.com/tpci/30C/30C_151_R_EN_SM.png","151/128"),"Sin imagen")
A25: 152/128 | B25: Mew ex | C25: Psíquico | D25: Special Illustration Rare | F25: Ilustrador aún no confirmado en las fuentes | H25: =IFERROR(_xlfn.IMAGE("https://limitlesstcg.nyc3.cdn.digitaloceanspaces.com/tpci/30C/30C_152_R_EN_SM.png","152/128"),"Sin imagen")
A26: 153/128 | B26: Sylveon ex | C26: Psíquico | D26: Special Illustration Rare | E26: You Iribi | H26: =IFERROR(_xlfn.IMAGE("https://limitlesstcg.nyc3.cdn.digitaloceanspaces.com/tpci/30C/30C_153_R_EN_SM.png","153/128"),"Sin imagen")
A27: 154/128 | B27: Gengar ex | C27: Oscuridad | D27: Special Illustration Rare | F27: Ilustrador aún no confirmado en las fuentes | H27: =IFERROR(_xlfn.IMAGE("https://limitlesstcg.nyc3.cdn.digitaloceanspaces.com/tpci/30C/30C_154_R_EN_SM.png","154/128"),"Sin imagen")
A28: 155/128 | B28: Jirachi ex | C28: Metal | D28: Special Illustration Rare | E28: AKIRA EGAWA | H28: =IFERROR(_xlfn.IMAGE("https://limitlesstcg.nyc3.cdn.digitaloceanspaces.com/tpci/30C/30C_155_R_EN_SM.png","155/128"),"Sin imagen")
A29: 156/128 | B29: Salamence ex | C29: Dragón | D29: Special Illustration Rare | E29: Ryota Murayama | H29: =IFERROR(_xlfn.IMAGE("https://limitlesstcg.nyc3.cdn.digitaloceanspaces.com/tpci/30C/30C_156_R_EN_SM.png","156/128"),"Sin imagen")
A30: 157/128 | B30: Mewtwo ex | C30: Psíquico | D30: Futuristic Rare | E30: YOSHIROTTEN | H30: =IFERROR(_xlfn.IMAGE("https://limitlesstcg.nyc3.cdn.digitaloceanspaces.com/tpci/30C/30C_157_R_EN_SM.png","157/128"),"Sin imagen")
A31: 158/128 | B31: Mew ex | C31: Psíquico | D31: Futuristic Rare | E31: YOSHIROTTEN | H31: =IFERROR(_xlfn.IMAGE("https://limitlesstcg.nyc3.cdn.digitaloceanspaces.com/tpci/30C/30C_158_R_EN_SM.png","158/128"),"Sin imagen")
A32: R/RGB | B32: Mew (Rojo) | C32: Psíquico | D32: Secret Rare (RGB) | E32: YOSHIROTTEN | F32: No figura en la lista oficial; descubierta en sobres | H32: =IFERROR(_xlfn.IMAGE("https://limitlesstcg.nyc3.cdn.digitaloceanspaces.com/tpci/30C/30C_R_R_EN_SM.png","R/RGB"),"Sin imagen")
A33: G/RGB | B33: Mew (Verde) | C33: Psíquico | D33: Secret Rare (RGB) | E33: YOSHIROTTEN | F33: No figura en la lista oficial; descubierta en sobres | H33: =IFERROR(_xlfn.IMAGE("https://limitlesstcg.nyc3.cdn.digitaloceanspaces.com/tpci/30C/30C_G_R_EN_SM.png","G/RGB"),"Sin imagen")
A34: B/RGB | B34: Mew (Azul) | C34: Psíquico | D34: Secret Rare (RGB) | E34: YOSHIROTTEN | F34: No figura en la lista oficial; descubierta en sobres | H34: =IFERROR(_xlfn.IMAGE("https://limitlesstcg.nyc3.cdn.digitaloceanspaces.com/tpci/30C/30C_B_R_EN_SM.png","B/RGB"),"Sin imagen")

Sheet Classic Collection
A1: N.º original | B1: Carta | C1: Notas | D1: ¿La tengo? | E1: Imagen
A2: 58/102 | B2: Pikachu | E2: =IFERROR(_xlfn.IMAGE("https://limitlesstcg.nyc3.cdn.digitaloceanspaces.com/tpci/30C/30C_CC1_R_EN_SM.png","Pikachu"),"Sin imagen")
A3: 4/102 | B3: Charizard | C3: Reimpresión del holo del Set Base | E3: =IFERROR(_xlfn.IMAGE("https://limitlesstcg.nyc3.cdn.digitaloceanspaces.com/tpci/30C/30C_CC2_R_EN_SM.png","Charizard"),"Sin imagen")
A4: 18/132 | B4: Misty | E4: =IFERROR(_xlfn.IMAGE("https://limitlesstcg.nyc3.cdn.digitaloceanspaces.com/tpci/30C/30C_CC3_R_EN_SM.png","Misty"),"Sin imagen")
A5: 69/132 | B5: Erika's Jigglypuff | E5: =IFERROR(_xlfn.IMAGE("https://limitlesstcg.nyc3.cdn.digitaloceanspaces.com/tpci/30C/30C_CC4_R_EN_SM.png","Erika's Jigglypuff"),"Sin imagen")
A6: 25/111 | B6: Sneasel | E6: =IFERROR(_xlfn.IMAGE("https://limitlesstcg.nyc3.cdn.digitaloceanspaces.com/tpci/30C/30C_CC5_R_EN_SM.png","Sneasel"),"Sin imagen")
A7: 106/105 | B7: Shining Celebi | E7: =IFERROR(_xlfn.IMAGE("https://limitlesstcg.nyc3.cdn.digitaloceanspaces.com/tpci/30C/30C_CC6_R_EN_SM.png","Shining Celebi"),"Sin imagen")
A8: 149/147 | B8: Lugia | C8: Reimpresión del Crystal Lugia de Aquapolis | E8: =IFERROR(_xlfn.IMAGE("https://limitlesstcg.nyc3.cdn.digitaloceanspaces.com/tpci/30C/30C_CC7_R_EN_SM.png","Lugia"),"Sin imagen")
A9: 5/109 | B9: Delcatty | E9: =IFERROR(_xlfn.IMAGE("https://limitlesstcg.nyc3.cdn.digitaloceanspaces.com/tpci/30C/30C_CC8_R_EN_SM.png","Delcatty"),"Sin imagen")
A10: 19/109 | B10: Dark Tyranitar | E10: =IFERROR(_xlfn.IMAGE("https://limitlesstcg.nyc3.cdn.digitaloceanspaces.com/tpci/30C/30C_CC9_R_EN_SM.png","Dark Tyranitar"),"Sin imagen")
A11: 108/115 | B11: Scizor ex | E11: =IFERROR(_xlfn.IMAGE("https://limitlesstcg.nyc3.cdn.digitaloceanspaces.com/tpci/30C/30C_CC10_R_EN_SM.png","Scizor ex"),"Sin imagen")
A12: 11/113 | B12: Metagross δ | E12: =IFERROR(_xlfn.IMAGE("https://limitlesstcg.nyc3.cdn.digitaloceanspaces.com/tpci/30C/30C_CC11_R_EN_SM.png","Metagross δ"),"Sin imagen")
A13: 106/106 | B13: Palkia LV.X | E13: =IFERROR(_xlfn.IMAGE("https://limitlesstcg.nyc3.cdn.digitaloceanspaces.com/tpci/30C/30C_CC12_R_EN_SM.png","Palkia LV.X"),"Sin imagen")
A14: 43/146 | B14: Uxie | E14: =IFERROR(_xlfn.IMAGE("https://limitlesstcg.nyc3.cdn.digitaloceanspaces.com/tpci/30C/30C_CC13_R_EN_SM.png","Uxie"),"Sin imagen")
A15: 47/127 | B15: Crobat G | E15: =IFERROR(_xlfn.IMAGE("https://limitlesstcg.nyc3.cdn.digitaloceanspaces.com/tpci/30C/30C_CC14_R_EN_SM.png","Crobat G"),"Sin imagen")
A16: 94/102 | B16: Gengar Prime | E16: =IFERROR(_xlfn.IMAGE("https://limitlesstcg.nyc3.cdn.digitaloceanspaces.com/tpci/30C/30C_CC15_R_EN_SM.png","Gengar Prime"),"Sin imagen")
A17: 99/102 | B17: Darkrai & Cresselia LEGEND – Parte superior | C17: Carta de 2 partes | E17: =IFERROR(_xlfn.IMAGE("https://limitlesstcg.nyc3.cdn.digitaloceanspaces.com/tpci/30C/30C_CC16_R_EN_SM.png","Darkrai & Cresselia LEGEND – Parte superior"),"Sin imagen")
A18: 100/102 | B18: Darkrai & Cresselia LEGEND – Parte inferior | C18: Carta de 2 partes | E18: =IFERROR(_xlfn.IMAGE("https://limitlesstcg.nyc3.cdn.digitaloceanspaces.com/tpci/30C/30C_CC17_R_EN_SM.png","Darkrai & Cresselia LEGEND – Parte inferior"),"Sin imagen")
A19: 101/101 | B19: N | E19: =IFERROR(_xlfn.IMAGE("https://limitlesstcg.nyc3.cdn.digitaloceanspaces.com/tpci/30C/30C_CC18_R_EN_SM.png","N"),"Sin imagen")
A20: 85/124 | B20: Rayquaza EX | E20: =IFERROR(_xlfn.IMAGE("https://limitlesstcg.nyc3.cdn.digitaloceanspaces.com/tpci/30C/30C_CC19_R_EN_SM.png","Rayquaza EX"),"Sin imagen")
A21: 11/101 | B21: Genesect EX | E21: =IFERROR(_xlfn.IMAGE("https://limitlesstcg.nyc3.cdn.digitaloceanspaces.com/tpci/30C/30C_CC20_R_EN_SM.png","Genesect EX"),"Sin imagen")
A22: 106/160 | B22: M Gardevoir EX | E22: =IFERROR(_xlfn.IMAGE("https://limitlesstcg.nyc3.cdn.digitaloceanspaces.com/tpci/30C/30C_CC21_R_EN_SM.png","M Gardevoir EX"),"Sin imagen")
A23: 41/122 | B23: Greninja BREAK | E23: =IFERROR(_xlfn.IMAGE("https://limitlesstcg.nyc3.cdn.digitaloceanspaces.com/tpci/30C/30C_CC22_R_EN_SM.png","Greninja BREAK"),"Sin imagen")
A24: 89/149 | B24: Solgaleo GX | E24: =IFERROR(_xlfn.IMAGE("https://limitlesstcg.nyc3.cdn.digitaloceanspaces.com/tpci/30C/30C_CC23_R_EN_SM.png","Solgaleo GX"),"Sin imagen")
A25: 57/111 | B25: Pheromosa GX | E25: =IFERROR(_xlfn.IMAGE("https://limitlesstcg.nyc3.cdn.digitaloceanspaces.com/tpci/30C/30C_CC24_R_EN_SM.png","Pheromosa GX"),"Sin imagen")
A26: 33/181 | B26: Pikachu & Zekrom GX | E26: =IFERROR(_xlfn.IMAGE("https://limitlesstcg.nyc3.cdn.digitaloceanspaces.com/tpci/30C/30C_CC25_R_EN_SM.png","Pikachu & Zekrom GX"),"Sin imagen")
A27: 138/202 | B27: Zacian V | E27: =IFERROR(_xlfn.IMAGE("https://limitlesstcg.nyc3.cdn.digitaloceanspaces.com/tpci/30C/30C_CC26_R_EN_SM.png","Zacian V"),"Sin imagen")
A28: 50/185 | B28: Raikou | E28: =IFERROR(_xlfn.IMAGE("https://limitlesstcg.nyc3.cdn.digitaloceanspaces.com/tpci/30C/30C_CC27_R_EN_SM.png","Raikou"),"Sin imagen")
A29: 114/264 | B29: Mew VMAX | E29: =IFERROR(_xlfn.IMAGE("https://limitlesstcg.nyc3.cdn.digitaloceanspaces.com/tpci/30C/30C_CC28_R_EN_SM.png","Mew VMAX"),"Sin imagen")
A30: 123/172 | B30: Arceus VSTAR | E30: =IFERROR(_xlfn.IMAGE("https://limitlesstcg.nyc3.cdn.digitaloceanspaces.com/tpci/30C/30C_CC29_R_EN_SM.png","Arceus VSTAR"),"Sin imagen")
A31: 203/193 | B31: Magikarp | E31: =IFERROR(_xlfn.IMAGE("https://limitlesstcg.nyc3.cdn.digitaloceanspaces.com/tpci/30C/30C_CC30_R_EN_SM.png","Magikarp"),"Sin imagen")

Sheet Energías
A1: Carta | B1: ¿La tengo?
A2: Energía Básica de Planta
A3: Energía Básica de Fuego
A4: Energía Básica de Agua
A5: Energía Básica de Rayo
A6: Energía Básica Psíquica
A7: Energía Básica de Lucha
A8: Energía Básica de Oscuridad
A9: Energía Básica de Metal
